<?xml version="1.0" ?>
<sdf version="1.6">
  <model name="bodyguard_drone">
    <!-- Base link (drone body) -->
    <link name="base_link">
      <pose>0 0 0.5 0 0 0</pose>
      <inertial>
        <mass>1.5</mass>
        <inertia>
          <ixx>0.03</ixx>
          <iyy>0.03</iyy>
          <izz>0.06</izz>
        </inertia>
      </inertial>
      
      <collision name="collision">
        <geometry>
          <box>
            <size>0.3 0.3 0.1</size>
          </box>
        </geometry>
      </collision>
      
      <visual name="visual">
        <geometry>
          <box>
            <size>0.3 0.3 0.1</size>
          </box>
        </geometry>
        <material>
          <ambient>0.2 0.2 0.2 1</ambient>
          <diffuse>0.3 0.3 0.3 1</diffuse>
        </material>
      </visual>

      <!-- Camera sensor -->
      <sensor name="camera" type="camera">
        <pose>0.15 0 0 0 0.3 0</pose>
        <camera>
          <horizontal_fov>1.047</horizontal_fov>
          <image>
            <width>640</width>
            <height>480</height>
          </image>
          <clip>
            <near>0.1</near>
            <far>100</far>
          </clip>
        </camera>
        <always_on>1</always_on>
        <update_rate>30</update_rate>
        <visualize>true</visualize>
        <plugin name="camera_controller" filename="libgazebo_ros_camera.so">
          <ros>
            <namespace>/drone</namespace>
            <remapping>image_raw:=camera/image_raw</remapping>
            <remapping>camera_info:=camera/camera_info</remapping>
          </ros>
          <camera_name>camera</camera_name>
          <frame_name>camera_link</frame_name>
        </plugin>
      </sensor>

      <!-- IMU sensor -->
      <sensor name="imu" type="imu">
        <always_on>true</always_on>
        <update_rate>100</update_rate>
        <imu>
          <angular_velocity>
            <x>
              <noise type="gaussian">
                <mean>0</mean>
                <stddev>0.009</stddev>
              </noise>
            </x>
            <y>
              <noise type="gaussian">
                <mean>0</mean>
                <stddev>0.009</stddev>
              </noise>
            </y>
            <z>
              <noise type="gaussian">
                <mean>0</mean>
                <stddev>0.009</stddev>
              </noise>
            </z>
          </angular_velocity>
          <linear_acceleration>
            <x>
              <noise type="gaussian">
                <mean>0</mean>
                <stddev>0.017</stddev>
              </noise>
            </x>
            <y>
              <noise type="gaussian">
                <mean>0</mean>
                <stddev>0.017</stddev>
              </noise>
            </y>
            <z>
              <noise type="gaussian">
                <mean>0</mean>
                <stddev>0.017</stddev>
              </noise>
            </z>
          </linear_acceleration>
        </imu>
        <plugin name="imu_plugin" filename="libgazebo_ros_imu_sensor.so">
          <ros>
            <namespace>/drone</namespace>
            <remapping>~/out:=imu</remapping>
          </ros>
          <frame_name>base_link</frame_name>
        </plugin>
      </sensor>
    </link>

    <!-- Rotor arm 1 (front right) -->
    <link name="rotor_1">
      <pose>0.15 -0.15 0.5 0 0 0</pose>
      <inertial>
        <mass>0.05</mass>
        <inertia>
          <ixx>0.0001</ixx>
          <iyy>0.0001</iyy>
          <izz>0.0002</izz>
        </inertia>
      </inertial>
      <collision name="collision">
        <geometry>
          <cylinder>
            <radius>0.08</radius>
            <length>0.01</length>
          </cylinder>
        </geometry>
      </collision>
      <visual name="visual">
        <geometry>
          <cylinder>
            <radius>0.08</radius>
            <length>0.01</length>
          </cylinder>
        </geometry>
        <material>
          <ambient>0.1 0.1 0.1 1</ambient>
          <diffuse>0.2 0.2 0.2 1</diffuse>
        </material>
      </visual>
    </link>

    <!-- Rotor arm 2 (rear right) -->
    <link name="rotor_2">
      <pose>-0.15 -0.15 0.5 0 0 0</pose>
      <inertial>
        <mass>0.05</mass>
        <inertia>
          <ixx>0.0001</ixx>
          <iyy>0.0001</iyy>
          <izz>0.0002</izz>
        </inertia>
      </inertial>
      <collision name="collision">
        <geometry>
          <cylinder>
            <radius>0.08</radius>
            <length>0.01</length>
          </cylinder>
        </geometry>
      </collision>
      <visual name="visual">
        <geometry>
          <cylinder>
            <radius>0.08</radius>
            <length>0.01</length>
          </cylinder>
        </geometry>
        <material>
          <ambient>0.1 0.1 0.1 1</ambient>
          <diffuse>0.2 0.2 0.2 1</diffuse>
        </material>
      </visual>
    </link>

    <!-- Rotor arm 3 (rear left) -->
    <link name="rotor_3">
      <pose>-0.15 0.15 0.5 0 0 0</pose>
      <inertial>
        <mass>0.05</mass>
        <inertia>
          <ixx>0.0001</ixx>
          <iyy>0.0001</iyy>
          <izz>0.0002</izz>
        </inertia>
      </inertial>
      <collision name="collision">
        <geometry>
          <cylinder>
            <radius>0.08</radius>
            <length>0.01</length>
          </cylinder>
        </geometry>
      </collision>
      <visual name="visual">
        <geometry>
          <cylinder>
            <radius>0.08</radius>
            <length>0.01</length>
          </cylinder>
        </geometry>
        <material>
          <ambient>0.1 0.1 0.1 1</ambient>
          <diffuse>0.2 0.2 0.2 1</diffuse>
        </material>
      </visual>
    </link>

    <!-- Rotor arm 4 (front left) -->
    <link name="rotor_4">
      <pose>0.15 0.15 0.5 0 0 0</pose>
      <inertial>
        <mass>0.05</mass>
        <inertia>
          <ixx>0.0001</ixx>
          <iyy>0.0001</iyy>
          <izz>0.0002</izz>
        </inertia>
      </inertial>
      <collision name="collision">
        <geometry>
          <cylinder>
            <radius>0.08</radius>
            <length>0.01</length>
          </cylinder>
        </geometry>
      </collision>
      <visual name="visual">
        <geometry>
          <cylinder>
            <radius>0.08</radius>
            <length>0.01</length>
          </cylinder>
        </geometry>
        <material>
          <ambient>0.1 0.1 0.1 1</ambient>
          <diffuse>0.2 0.2 0.2 1</diffuse>
        </material>
      </visual>
    </link>

    <!-- Joints connecting rotors to base -->
    <joint name="rotor_1_joint" type="revolute">
      <parent>base_link</parent>
      <child>rotor_1</child>
      <axis>
        <xyz>0 0 1</xyz>
        <limit>
          <lower>-1e16</lower>
          <upper>1e16</upper>
        </limit>
      </axis>
    </joint>

    <joint name="rotor_2_joint" type="revolute">
      <parent>base_link</parent>
      <child>rotor_2</child>
      <axis>
        <xyz>0 0 1</xyz>
        <limit>
          <lower>-1e16</lower>
          <upper>1e16</upper>
        </limit>
      </axis>
    </joint>

    <joint name="rotor_3_joint" type="revolute">
      <parent>base_link</parent>
      <child>rotor_3</child>
      <axis>
        <xyz>0 0 1</xyz>
        <limit>
          <lower>-1e16</lower>
          <upper>1e16</upper>
        </limit>
      </axis>
    </joint>

    <joint name="rotor_4_joint" type="revolute">
      <parent>base_link</parent>
      <child>rotor_4</child>
      <axis>
        <xyz>0 0 1</xyz>
        <limit>
          <lower>-1e16</lower>
          <upper>1e16</upper>
        </limit>
      </axis>
    </joint>

    <!-- Drone control plugin -->
    <plugin name="drone_control" filename="libgazebo_ros_planar_move.so">
      <ros>
        <namespace>/drone</namespace>
        <remapping>cmd_vel:=cmd_vel</remapping>
        <remapping>odom:=odom</remapping>
      </ros>
      <update_rate>100</update_rate>
      <publish_rate>10</publish_rate>
      <publish_odom>true</publish_odom>
      <publish_odom_tf>true</publish_odom_tf>
      <odometry_frame>odom</odometry_frame>
      <robot_base_frame>base_link</robot_base_frame>
    </plugin>

  </model>
</sdf>
