<?xml version="1.0" ?>
<sdf version="1.6">
  <model name="person_with_ring">
    <!-- Base/Torso -->
    <link name="torso">
      <pose>0 0 0.9 0 0 0</pose>
      <inertial>
        <mass>50</mass>
        <inertia>
          <ixx>2.0</ixx>
          <iyy>2.0</iyy>
          <izz>0.5</izz>
        </inertia>
      </inertial>
      <collision name="collision">
        <geometry>
          <box>
            <size>0.4 0.25 0.6</size>
          </box>
        </geometry>
      </collision>
      <visual name="visual">
        <geometry>
          <box>
            <size>0.4 0.25 0.6</size>
          </box>
        </geometry>
        <material>
          <ambient>0.2 0.4 0.8 1</ambient>
          <diffuse>0.3 0.5 0.9 1</diffuse>
        </material>
      </visual>
    </link>

    <!-- Head -->
    <link name="head">
      <pose>0 0 1.5 0 0 0</pose>
      <inertial>
        <mass>5</mass>
        <inertia>
          <ixx>0.1</ixx>
          <iyy>0.1</iyy>
          <izz>0.1</izz>
        </inertia>
      </inertial>
      <collision name="collision">
        <geometry>
          <sphere>
            <radius>0.15</radius>
          </sphere>
        </geometry>
      </collision>
      <visual name="visual">
        <geometry>
          <sphere>
            <radius>0.15</radius>
          </sphere>
        </geometry>
        <material>
          <ambient>0.9 0.7 0.6 1</ambient>
          <diffuse>1.0 0.8 0.7 1</diffuse>
        </material>
      </visual>
    </link>

    <!-- Right arm -->
    <link name="right_arm">
      <pose>0.25 0 0.9 0 0 0</pose>
      <inertial>
        <mass>3</mass>
        <inertia>
          <ixx>0.05</ixx>
          <iyy>0.05</iyy>
          <izz>0.01</izz>
        </inertia>
      </inertial>
      <collision name="collision">
        <geometry>
          <cylinder>
            <radius>0.04</radius>
            <length>0.5</length>
          </cylinder>
        </geometry>
      </collision>
      <visual name="visual">
        <geometry>
          <cylinder>
            <radius>0.04</radius>
            <length>0.5</length>
          </cylinder>
        </geometry>
        <material>
          <ambient>0.9 0.7 0.6 1</ambient>
          <diffuse>1.0 0.8 0.7 1</diffuse>
        </material>
      </visual>
    </link>

    <!-- Left arm -->
    <link name="left_arm">
      <pose>-0.25 0 0.9 0 0 0</pose>
      <inertial>
        <mass>3</mass>
        <inertia>
          <ixx>0.05</ixx>
          <iyy>0.05</iyy>
          <izz>0.01</izz>
        </inertia>
      </inertial>
      <collision name="collision">
        <geometry>
          <cylinder>
            <radius>0.04</radius>
            <length>0.5</length>
          </cylinder>
        </geometry>
      </collision>
      <visual name="visual">
        <geometry>
          <cylinder>
            <radius>0.04</radius>
            <length>0.5</length>
          </cylinder>
        </geometry>
        <material>
          <ambient>0.9 0.7 0.6 1</ambient>
          <diffuse>1.0 0.8 0.7 1</diffuse>
        </material>
      </visual>
    </link>

    <!-- Ring on right hand -->
    <link name="ring">
      <pose>0.25 0 0.65 0 1.57 0</pose>
      <inertial>
        <mass>0.01</mass>
        <inertia>
          <ixx>0.0001</ixx>
          <iyy>0.0001</iyy>
          <izz>0.0001</izz>
        </inertia>
      </inertial>
      <visual name="visual">
        <geometry>
          <cylinder>
            <radius>0.015</radius>
            <length>0.005</length>
          </cylinder>
        </geometry>
        <material>
          <ambient>1.0 0.84 0.0 1</ambient>
          <diffuse>1.0 0.84 0.0 1</diffuse>
        </material>
      </visual>
    </link>

    <!-- Right leg -->
    <link name="right_leg">
      <pose>0.1 0 0.3 0 0 0</pose>
      <inertial>
        <mass>8</mass>
        <inertia>
          <ixx>0.2</ixx>
          <iyy>0.2</iyy>
          <izz>0.05</izz>
        </inertia>
      </inertial>
      <collision name="collision">
        <geometry>
          <cylinder>
            <radius>0.08</radius>
            <length>0.6</length>
          </cylinder>
        </geometry>
      </collision>
      <visual name="visual">
        <geometry>
          <cylinder>
            <radius>0.08</radius>
            <length>0.6</length>
          </cylinder>
        </geometry>
        <material>
          <ambient>0.2 0.2 0.4 1</ambient>
          <diffuse>0.3 0.3 0.5 1</diffuse>
        </material>
      </visual>
    </link>

    <!-- Left leg -->
    <link name="left_leg">
      <pose>-0.1 0 0.3 0 0 0</pose>
      <inertial>
        <mass>8</mass>
        <inertia>
          <ixx>0.2</ixx>
          <iyy>0.2</iyy>
          <izz>0.05</izz>
        </inertia>
      </inertial>
      <collision name="collision">
        <geometry>
          <cylinder>
            <radius>0.08</radius>
            <length>0.6</length>
          </cylinder>
        </geometry>
      </collision>
      <visual name="visual">
        <geometry>
          <cylinder>
            <radius>0.08</radius>
            <length>0.6</length>
          </cylinder>
        </geometry>
        <material>
          <ambient>0.2 0.2 0.4 1</ambient>
          <diffuse>0.3 0.3 0.5 1</diffuse>
        </material>
      </visual>
    </link>

    <!-- Joints -->
    <joint name="torso_to_head" type="fixed">
      <parent>torso</parent>
      <child>head</child>
    </joint>

    <joint name="torso_to_right_arm" type="revolute">
      <parent>torso</parent>
      <child>right_arm</child>
      <axis>
        <xyz>0 1 0</xyz>
        <limit>
          <lower>-1.5</lower>
          <upper>1.5</upper>
        </limit>
      </axis>
    </joint>

    <joint name="torso_to_left_arm" type="revolute">
      <parent>torso</parent>
      <child>left_arm</child>
      <axis>
        <xyz>0 1 0</xyz>
        <limit>
          <lower>-1.5</lower>
          <upper>1.5</upper>
        </limit>
      </axis>
    </joint>

    <joint name="right_arm_to_ring" type="fixed">
      <parent>right_arm</parent>
      <child>ring</child>
    </joint>

    <joint name="torso_to_right_leg" type="revolute">
      <parent>torso</parent>
      <child>right_leg</child>
      <axis>
        <xyz>0 1 0</xyz>
        <limit>
          <lower>-0.5</lower>
          <upper>0.5</upper>
        </limit>
      </axis>
    </joint>

    <joint name="torso_to_left_leg" type="revolute">
      <parent>torso</parent>
      <child>left_leg</child>
      <axis>
        <xyz>0 1 0</xyz>
        <limit>
          <lower>-0.5</lower>
          <upper>0.5</upper>
        </limit>
      </axis>
    </joint>

  </model>
</sdf>
